<?xml version="1.0" encoding="UTF-8"?>
<!-- Generated by org.testng.reporters.JUnitXMLReporter -->
<testsuite ignored="0" hostname="AFSWWI9CYZ2H4A" failures="1" tests="8" name="Default test" time="3.633" errors="0" timestamp="2023-01-26T10:43:15 CST">
  <testcase classname="com.developerscorner.provider.service.UserServiceTest" name="shouldDeleteAUser" time="0.056"/>
  <testcase classname="com.developerscorner.provider.service.UserServiceTest" name="shouldFindAllUsers" time="0.002"/>
  <testcase classname="com.developerscorner.provider.service.UserServiceTest" name="shouldFindUserByEmail" time="0.007"/>
  <testcase classname="com.developerscorner.provider.service.UserServiceTest" name="shouldFindUserById" time="0.004"/>
  <testcase classname="com.developerscorner.provider.service.UserServiceTest" name="shouldSaveAUser" time="0.015"/>
  <testcase classname="com.developerscorner.provider.service.UserServiceTest" name="shouldThrowNotFoundExceptionIfUserByEmailNotExists" time="0.003">
    <failure type="org.testng.TestException" message="
Method UserServiceTest.shouldThrowNotFoundExceptionIfUserByEmailNotExists()[pri:0, instance:com.developerscorner.provider.service.UserServiceTest@161aa04a] should have thrown an exception of type class com.developerscorner.provider.exception.NotFoundException">
      <![CDATA[org.testng.TestException: 
Method UserServiceTest.shouldThrowNotFoundExceptionIfUserByEmailNotExists()[pri:0, instance:com.developerscorner.provider.service.UserServiceTest@161aa04a] should have thrown an exception of type class com.developerscorner.provider.exception.NotFoundException
at org.testng.internal.ExpectedExceptionsHolder.noException(ExpectedExceptionsHolder.java:82)
at org.testng.internal.TestInvoker.considerExceptions(TestInvoker.java:749)
at org.testng.internal.TestInvoker.invokeMethod(TestInvoker.java:634)
at org.testng.internal.TestInvoker.invokeTestMethod(TestInvoker.java:173)
at org.testng.internal.MethodRunner.runInSequence(MethodRunner.java:46)
at org.testng.internal.TestInvoker$MethodInvocationAgent.invoke(TestInvoker.java:824)
at org.testng.internal.TestInvoker.invokeTestMethods(TestInvoker.java:146)
at org.testng.internal.TestMethodWorker.invokeTestMethods(TestMethodWorker.java:146)
at org.testng.internal.TestMethodWorker.run(TestMethodWorker.java:128)
at java.base/java.util.ArrayList.forEach(ArrayList.java:1511)
at org.testng.TestRunner.privateRun(TestRunner.java:794)
at org.testng.TestRunner.run(TestRunner.java:596)
at org.testng.SuiteRunner.runTest(SuiteRunner.java:377)
at org.testng.SuiteRunner.runSequentially(SuiteRunner.java:371)
at org.testng.SuiteRunner.privateRun(SuiteRunner.java:332)
at org.testng.SuiteRunner.run(SuiteRunner.java:276)
at org.testng.SuiteRunnerWorker.runSuite(SuiteRunnerWorker.java:53)
at org.testng.SuiteRunnerWorker.run(SuiteRunnerWorker.java:96)
at org.testng.TestNG.runSuitesSequentially(TestNG.java:1212)
at org.testng.TestNG.runSuitesLocally(TestNG.java:1134)
at org.testng.TestNG.runSuites(TestNG.java:1063)
at org.testng.TestNG.run(TestNG.java:1031)
at org.testng.remote.AbstractRemoteTestNG.run(AbstractRemoteTestNG.java:115)
at org.testng.remote.RemoteTestNG.initAndRun(RemoteTestNG.java:251)
at org.testng.remote.RemoteTestNG.main(RemoteTestNG.java:77)
]]>
    </failure>
  </testcase> <!-- shouldThrowNotFoundExceptionIfUserByEmailNotExists -->
  <testcase classname="com.developerscorner.provider.service.UserServiceTest" name="shouldThrowNotFoundExceptionIfUserByIdNotExists" time="0.002"/>
  <testcase classname="com.developerscorner.provider.service.UserServiceTest" name="shouldUpdateAUser" time="0.007"/>
</testsuite> <!-- Default test -->
